Workbook
Name Avearage_Current_Price: Analysis!$B$9
Name Price_Q1: Analysis!$B$2
Name Price_Q2: Analysis!$B$3
Name Price_Q3: Analysis!$B$3
Name Slicer_Discount: #N/A
Name Slicer_Discount_Category: #N/A
Name Slicer_Price_Category: #N/A
Name Slicer_Rating_Category: #N/A

Sheet Raw Data
A1: Product | B1: Current price | C1: old price | D1: Discount | E1: Review | F1: Ratingd
A2: 115 Piece Set Of Multifunctional Precision Screwdrivers | B2: KSh 950 | C2: KSh 1,525 | D2: 0.38 | E2: -2 | F2: 4.5 out of 5
A3: Metal Decorative Hooks Key Hangers Entryway Wall Hooks Towel Hooks - Home | B3: KSh 527 | C3: KSh 999 | D3: 0.47 | E3: -14 | F3: 4.1 out of 5
A4: Portable Mini Cordless Car Vacuum Cleaner - Blue | B4: KSh 2,199 | C4: KSh 2,923 | D4: 0.25 | E4: -24 | F4: 4.6 out of 5
A5: Weighing Scale Digital Bathroom Body Fat Scale USB-Black | B5: KSh 1,580 | C5: KSh 2,499 | D5: 0.37 | E5: -7 | F5: 4.7 out of 5
A6: Portable Home Small Air Humidifier 3-Speed Fan - Green | B6: KSh 1,740 | C6: KSh 2,356 | D6: 0.26 | E6: -5 | F6: 4.8 out of 5
A7: 220V 60W Electric Soldering Iron Kits With Tools, Tips, And Multimeter | B7: KSh 2,999 | C7: KSh 3,290 | D7: 0.09 | E7: -15 | F7: 4 out of 5
A8: 137 Pieces Cake Decorating Tool Set Baking Supplies | B8: KSh 2,319 | C8: KSh 3,032 | D8: 0.24 | E8: -55 | F8: 4.6 out of 5
A9: Desk Foldable Fan Adjustable Fan Strong Wind 3 Gear Usb | B9: KSh 988 | C9: KSh 1,580 | D9: 0.37 | E9: -2 | F9: 4 out of 5
A10: LASA FOLDING TABLE SERVING STAND | B10: KSh 1,274 | C10: KSh 2,800 | D10: 0.55 | E10: -5 | F10: 4.8 out of 5
A11: 13 In 1 Home Repair Tools Box Kit Set | B11: KSh 1,600 | C11: KSh 2,929 | D11: 0.45 | E11: -5 | F11: 3.8 out of 5
A12: Genebre 115 In 1 Screwdriver Repairing Tool Set For IPhone Cellphone Hand Tool | B12: KSh 799 | C12: KSh 999 | D12: 0.2 | E12: -12 | F12: 4.1 out of 5
A13: 100 Pcs Crochet Hook Tool Set Knitting Hook Set With Box | B13: KSh 990 | C13: KSh 1,500 | D13: 0.34 | E13: -39 | F13: 4.7 out of 5
... A22: 3PCS Single Head Knitting Crochet Sweater Needle Set | B22: KSh 38 | C22: KSh 80 | D22: 0.53 | E22: -13 | F22: 3.3 out of 5
A23: 4pcs Bathroom/Kitchen Towel Rack,Roll Paper Holder,Towel Bars,Hook | B23: KSh 1,860 | C23: KSh 3,220 | D23: 0.42
A24: LED Romantic Spaceship Starry Sky Projector,Children's Bedroom Night Light-Blue | B24: KSh 880 | C24: KSh 1,350 | D24: 0.35 | E24: -6 | F24: 4 out of 5
A25: Foldable Overbed Table/Desk | B25: KSh 1,650 | C25: KSh 2,150 | D25: 0.23 | E25: -14 | F25: 4.4 out of 5
A26: LASA 3 Tier Bamboo Shoe Bench Storage Shelf | B26: KSh 2,048 | C26: KSh 4,500 | D26: 0.54 | E26: -7 | F26: 4.3 out of 5
A27: Electronic Digital Display Vernier Caliper | B27: KSh 420 | C27: KSh 647 | D27: 0.35 | E27: -49 | F27: 4.6 out of 5
A28: Portable Wardrobe Nonwoven With 3 Hanging Rods And 6 Storage Shelves | B28: KSh 2,880 | C28: KSh 3,520 | D28: 0.18 | E28: -12 | F28: 3.8 out of 5
A29: 12 Litre Black Insulated Lunch Box | B29: KSh 1,350 | C29: KSh 1,990 | D29: 0.32 | E29: -13 | F29: 3.8 out of 5
A30: 52 Pieces Cake Decorating Tool Set Gift Kit Baking Supplies | B30: KSh 1,758 | C30: KSh 2,499 | D30: 0.3 | E30: -20 | F30: 4.1 out of 5
A31: MultiFunctional Storage Rack Multi-layer Bookshelf | B31: KSh 2,200 | C31: KSh 4,080 | D31: 0.46
A32: Exfoliate And Exfoliate Face Towel - Black | B32: KSh 185 | C32: KSh 382 | D32: 0.52 | E32: -9 | F32: 4.3 out of 5
A33: 12 Litre Insulated Lunch Box Grey | B33: KSh 980 | C33: KSh 1,490 | D33: 0.34 | E33: -12 | F33: 4.7 out of 5
A34: LED Eye Protection Desk Lamp , Study, Reading, USB Fan - Double Pen Holder | B34: KSh 1,820 | C34: KSh 3,490 | D34: 0.48 | E34: -9 | F34: 4.3 out of 5
A35: 53Pcs/Set Yarn Knitting Crochet Hooks With Bag - Fortune Cat | B35: KSh 1,940 | C35: KSh 2,650 | D35: 0.27 | E35: -20 | F35: 4.7 out of 5
A36: 53 Pieces/Set Yarn Knitting Crochet Hooks With Bag - Pansies | B36: KSh 1,980 | C36: KSh 2,699 | D36: 0.27 | E36: -32 | F36: 4.5 out of 5
A37: DIY File Folder, Office Drawer File Holder, Pen Holder, Desktop Storage Rack | B37: KSh 1,620 | C37: KSh 2,690 | D37: 0.4 | E37: -1 | F37: 5 out of 5
A38: Classic Black Cat Cotton Hemp Pillow Case For Home Car | B38: KSh 171 | C38: KSh 360 | D38: 0.53 | E38: -2 | F38: 5 out of 5
A39: Punch-free Great Load Bearing Bathroom Storage Rack Wall Shelf-White | B39: KSh 389 | C39: KSh 656 | D39: 0.41 | E39: -36 | F39: 4.3 out of 5
A40: 1/2/3 Seater Elastic Sofa Cover,Living Room/Home Decor Chair Cover-Grey | B40: KSh 1,620 - KSh 1,980 | C40: KSh 2,200 - KSh 3,200 | D40: 0.38 | E40: -2 | F40: 4.5 out of 5
A41: LASA Stainless Steel Double Wall Mount Soap Dispenser - 500ml | B41: KSh 2,750 | C41: KSh 4,471 | D41: 0.38
A42: 4M Float Switch Water Level Controller -Water Tank | B42: KSh 475 | C42: KSh 931 | D42: 0.49
A43: Modern Sofa Throw Pillow Cover-45x45cm-Blue&Red | B43: KSh 238 | C43: KSh 476 | D43: 0.5
A44: Balloon Insert, Birthday Party Balloon Set, PU Leather | B44: KSh 610 | C44: KSh 1,060 | D44: 0.42
A45: Balloon Insert, Birthday Party Balloon Set, PU Leather | B45: KSh 610 | C45: KSh 1,060 | D45: 0.42
A46: Shower Cap Wide Elastic Band Cover Reusable Bashroom Cap | B46: KSh 2,132 | C46: KSh 2,169 | D46: 0.02
A47: Christmas Elk Fence Yard Lawn Decorations Cute For Holidays | B47: KSh 999 | C47: KSh 2,000 | D47: 0.5
A48: 60W Hot Melt Glue Sprayer - Efficient And Stable Glue Dispensing | B48: KSh 1,190 | C48: KSh 1,785 | D48: 0.33
...

Sheet Cleaned Data
A1: Product | B1: Current Price | C1: Old Price | D1: Price Category | E1: Discount Amount | F1: Discount | G1: Discount Category | H1: Review | I1: Rating | J1: Rating Category
A2: 115 Piece Set Of Multifunctional Precision Screwdrivers | B2: 950 | C2: 1525 | D2: =IF(tblProducts[[#This Row],[Current Price]]="","Missing",IF(tblProducts[[#This Row],[Current Price]]<Price_Q1,"Low Price",IF(tblProducts[[#This Row],[Current Price]]<Price_Q3,"Medium Price","High Price"))) -> Medium Price | E2: =tblProducts[[#This Row],[Old Price]]-tblProducts[[#This Row],[Current Price]] -> 575 | F2: 0.38 | G2: =IF(tblProducts[[#This Row],[Discount]]="","Missing",IF(tblProducts[[#This Row],[Discount]]<20%,"Low Discount",IF(tblProducts[[#This Row],[Discount]]<=40%,"Medium Discount","High Discount"))) -> Medium Discount | H2: 2 | I2: 4.5 | J2: =IF(tblProducts[[#This Row],[Rating]]="","Missing",IF(tblProducts[[#This Row],[Rating]]<3,"Poor",IF(tblProducts[[#This Row],[Rating]]<=4,"Average",IF(tblProducts[[#This Row],[Rating]]<4.5, "Unclassified","Excellent")))) -> Excellent
A3: Metal Decorative Hooks Key Hangers Entryway Wall Hooks Towel Hooks - Home | B3: 527 | C3: 999 | D3: =IF(tblProducts[[#This Row],[Current Price]]="","Missing",IF(tblProducts[[#This Row],[Current Price]]<Price_Q1,"Low Price",IF(tblProducts[[#This Row],[Current Price]]<Price_Q3,"Medium Price","High Price"))) -> Medium Price | E3: =tblProducts[[#This Row],[Old Price]]-tblProducts[[#This Row],[Current Price]] -> 472 | F3: 0.47 | G3: =IF(tblProducts[[#This Row],[Discount]]="","Missing",IF(tblProducts[[#This Row],[Discount]]<20%,"Low Discount",IF(tblProducts[[#This Row],[Discount]]<=40%,"Medium Discount","High Discount"))) -> High Discount | H3: 14 | I3: 4.1 | J3: =IF(tblProducts[[#This Row],[Rating]]="","Missing",IF(tblProducts[[#This Row],[Rating]]<3,"Poor",IF(tblProducts[[#This Row],[Rating]]<=4,"Average",IF(tblProducts[[#This Row],[Rating]]<4.5, "Unclassified","Excellent")))) -> Unclassified
A4: Portable Mini Cordless Car Vacuum Cleaner - Blue | B4: 2199 | C4: 2923 | D4: =IF(tblProducts[[#This Row],[Current Price]]="","Missing",IF(tblProducts[[#This Row],[Current Price]]<Price_Q1,"Low Price",IF(tblProducts[[#This Row],[Current Price]]<Price_Q3,"Medium Price","High Price"))) -> High Price | E4: =tblProducts[[#This Row],[Old Price]]-tblProducts[[#This Row],[Current Price]] -> 724 | F4: 0.25 | G4: =IF(tblProducts[[#This Row],[Discount]]="","Missing",IF(tblProducts[[#This Row],[Discount]]<20%,"Low Discount",IF(tblProducts[[#This Row],[Discount]]<=40%,"Medium Discount","High Discount"))) -> Medium Discount | H4: 24 | I4: 4.6 | J4: =IF(tblProducts[[#This Row],[Rating]]="","Missing",IF(tblProducts[[#This Row],[Rating]]<3,"Poor",IF(tblProducts[[#This Row],[Rating]]<=4,"Average",IF(tblProducts[[#This Row],[Rating]]<4.5, "Unclassified","Excellent")))) -> Excellent
A5: Weighing Scale Digital Bathroom Body Fat Scale USB-Black | B5: 1580 | C5: 2499 | D5: =IF(tblProducts[[#This Row],[Current Price]]="","Missing",IF(tblProducts[[#This Row],[Current Price]]<Price_Q1,"Low Price",IF(tblProducts[[#This Row],[Current Price]]<Price_Q3,"Medium Price","High Price"))) -> Medium Price | E5: =tblProducts[[#This Row],[Old Price]]-tblProducts[[#This Row],[Current Price]] -> 919 | F5: 0.37 | G5: =IF(tblProducts[[#This Row],[Discount]]="","Missing",IF(tblProducts[[#This Row],[Discount]]<20%,"Low Discount",IF(tblProducts[[#This Row],[Discount]]<=40%,"Medium Discount","High Discount"))) -> Medium Discount | H5: 7 | I5: 4.7 | J5: =IF(tblProducts[[#This Row],[Rating]]="","Missing",IF(tblProducts[[#This Row],[Rating]]<3,"Poor",IF(tblProducts[[#This Row],[Rating]]<=4,"Average",IF(tblProducts[[#This Row],[Rating]]<4.5, "Unclassified","Excellent")))) -> Excellent
A6: Portable Home Small Air Humidifier 3-Speed Fan - Green | B6: 1740 | C6: 2356 | D6: =IF(tblProducts[[#This Row],[Current Price]]="","Missing",IF(tblProducts[[#This Row],[Current Price]]<Price_Q1,"Low Price",IF(tblProducts[[#This Row],[Current Price]]<Price_Q3,"Medium Price","High Price"))) -> High Price | E6: =tblProducts[[#This Row],[Old Price]]-tblProducts[[#This Row],[Current Price]] -> 616 | F6: 0.26 | G6: =IF(tblProducts[[#This Row],[Discount]]="","Missing",IF(tblProducts[[#This Row],[Discount]]<20%,"Low Discount",IF(tblProducts[[#This Row],[Discount]]<=40%,"Medium Discount","High Discount"))) -> Medium Discount | H6: 5 | I6: 4.8 | J6: =IF(tblProducts[[#This Row],[Rating]]="","Missing",IF(tblProducts[[#This Row],[Rating]]<3,"Poor",IF(tblProducts[[#This Row],[Rating]]<=4,"Average",IF(tblProducts[[#This Row],[Rating]]<4.5, "Unclassified","Excellent")))) -> Excellent
A7: 220V 60W Electric Soldering Iron Kits With Tools, Tips, And Multimeter | B7: 2999 | C7: 3290 | D7: =IF(tblProducts[[#This Row],[Current Price]]="","Missing",IF(tblProducts[[#This Row],[Current Price]]<Price_Q1,"Low Price",IF(tblProducts[[#This Row],[Current Price]]<Price_Q3,"Medium Price","High Price"))) -> High Price | E7: =tblProducts[[#This Row],[Old Price]]-tblProducts[[#This Row],[Current Price]] -> 291 | F7: 0.09 | G7: =IF(tblProducts[[#This Row],[Discount]]="","Missing",IF(tblProducts[[#This Row],[Discount]]<20%,"Low Discount",IF(tblProducts[[#This Row],[Discount]]<=40%,"Medium Discount","High Discount"))) -> Low Discount | H7: 15 | I7: 4 | J7: =IF(tblProducts[[#This Row],[Rating]]="","Missing",IF(tblProducts[[#This Row],[Rating]]<3,"Poor",IF(tblProducts[[#This Row],[Rating]]<=4,"Average",IF(tblProducts[[#This Row],[Rating]]<4.5, "Unclassified","Excellent")))) -> Average
A8: 137 Pieces Cake Decorating Tool Set Baking Supplies | B8: 2319 | C8: 3032 | D8: =IF(tblProducts[[#This Row],[Current Price]]="","Missing",IF(tblProducts[[#This Row],[Current Price]]<Price_Q1,"Low Price",IF(tblProducts[[#This Row],[Current Price]]<Price_Q3,"Medium Price","High Price"))) -> High Price | E8: =tblProducts[[#This Row],[Old Price]]-tblProducts[[#This Row],[Current Price]] -> 713 | F8: 0.24 | G8: =IF(tblProducts[[#This Row],[Discount]]="","Missing",IF(tblProducts[[#This Row],[Discount]]<20%,"Low Discount",IF(tblProducts[[#This Row],[Discount]]<=40%,"Medium Discount","High Discount"))) -> Medium Discount | H8: 55 | I8: 4.6 | J8: =IF(tblProducts[[#This Row],[Rating]]="","Missing",IF(tblProducts[[#This Row],[Rating]]<3,"Poor",IF(tblProducts[[#This Row],[Rating]]<=4,"Average",IF(tblProducts[[#This Row],[Rating]]<4.5, "Unclassified","Excellent")))) -> Excellent
A9: Desk Foldable Fan Adjustable Fan Strong Wind 3 Gear Usb | B9: 988 | C9: 1580 | D9: =IF(tblProducts[[#This Row],[Current Price]]="","Missing",IF(tblProducts[[#This Row],[Current Price]]<Price_Q1,"Low Price",IF(tblProducts[[#This Row],[Current Price]]<Price_Q3,"Medium Price","High Price"))) -> Medium Price | E9: =tblProducts[[#This Row],[Old Price]]-tblProducts[[#This Row],[Current Price]] -> 592 | F9: 0.37 | G9: =IF(tblProducts[[#This Row],[Discount]]="","Missing",IF(tblProducts[[#This Row],[Discount]]<20%,"Low Discount",IF(tblProducts[[#This Row],[Discount]]<=40%,"Medium Discount","High Discount"))) -> Medium Discount | H9: 2 | I9: 4 | J9: =IF(tblProducts[[#This Row],[Rating]]="","Missing",IF(tblProducts[[#This Row],[Rating]]<3,"Poor",IF(tblProducts[[#This Row],[Rating]]<=4,"Average",IF(tblProducts[[#This Row],[Rating]]<4.5, "Unclassified","Excellent")))) -> Average
A10: LASA FOLDING TABLE SERVING STAND | B10: 1274 | C10: 2800 | D10: =IF(tblProducts[[#This Row],[Current Price]]="","Missing",IF(tblProducts[[#This Row],[Current Price]]<Price_Q1,"Low Price",IF(tblProducts[[#This Row],[Current Price]]<Price_Q3,"Medium Price","High Price"))) -> Medium Price | E10: =tblProducts[[#This Row],[Old Price]]-tblProducts[[#This Row],[Current Price]] -> 1526 | F10: 0.55 | G10: =IF(tblProducts[[#This Row],[Discount]]="","Missing",IF(tblProducts[[#This Row],[Discount]]<20%,"Low Discount",IF(tblProducts[[#This Row],[Discount]]<=40%,"Medium Discount","High Discount"))) -> High Discount | H10: 5 | I10: 4.8 | J10: =IF(tblProducts[[#This Row],[Rating]]="","Missing",IF(tblProducts[[#This Row],[Rating]]<3,"Poor",IF(tblProducts[[#This Row],[Rating]]<=4,"Average",IF(tblProducts[[#This Row],[Rating]]<4.5, "Unclassified","Excellent")))) -> Excellent
A11: 13 In 1 Home Repair Tools Box Kit Set | B11: 1600 | C11: 2929 | D11: =IF(tblProducts[[#This Row],[Current Price]]="","Missing",IF(tblProducts[[#This Row],[Current Price]]<Price_Q1,"Low Price",IF(tblProducts[[#This Row],[Current Price]]<Price_Q3,"Medium Price","High Price"))) -> Medium Price | E11: =tblProducts[[#This Row],[Old Price]]-tblProducts[[#This Row],[Current Price]] -> 1329 | F11: 0.45 | G11: =IF(tblProducts[[#This Row],[Discount]]="","Missing",IF(tblProducts[[#This Row],[Discount]]<20%,"Low Discount",IF(tblProducts[[#This Row],[Discount]]<=40%,"Medium Discount","High Discount"))) -> High Discount | H11: 5 | I11: 3.8 | J11: =IF(tblProducts[[#This Row],[Rating]]="","Missing",IF(tblProducts[[#This Row],[Rating]]<3,"Poor",IF(tblProducts[[#This Row],[Rating]]<=4,"Average",IF(tblProducts[[#This Row],[Rating]]<4.5, "Unclassified","Excellent")))) -> Average
A12: Genebre 115 In 1 Screwdriver Repairing Tool Set For IPhone Cellphone Hand Tool | B12: 799 | C12: 999 | D12: =IF(tblProducts[[#This Row],[Current Price]]="","Missing",IF(tblProducts[[#This Row],[Current Price]]<Price_Q1,"Low Price",IF(tblProducts[[#This Row],[Current Price]]<Price_Q3,"Medium Price","High Price"))) -> Medium Price | E12: =tblProducts[[#This Row],[Old Price]]-tblProducts[[#This Row],[Current Price]] -> 200 | F12: 0.2 | G12: =IF(tblProducts[[#This Row],[Discount]]="","Missing",IF(tblProducts[[#This Row],[Discount]]<20%,"Low Discount",IF(tblProducts[[#This Row],[Discount]]<=40%,"Medium Discount","High Discount"))) -> Medium Discount | H12: 12 | I12: 4.1 | J12: =IF(tblProducts[[#This Row],[Rating]]="","Missing",IF(tblProducts[[#This Row],[Rating]]<3,"Poor",IF(tblProducts[[#This Row],[Rating]]<=4,"Average",IF(tblProducts[[#This Row],[Rating]]<4.5, "Unclassified","Excellent")))) -> Unclassified
A13: 100 Pcs Crochet Hook Tool Set Knitting Hook Set With Box | B13: 990 | C13: 1500 | D13: =IF(tblProducts[[#This Row],[Current Price]]="","Missing",IF(tblProducts[[#This Row],[Current Price]]<Price_Q1,"Low Price",IF(tblProducts[[#This Row],[Current Price]]<Price_Q3,"Medium Price","High Price"))) -> Medium Price | E13: =tblProducts[[#This Row],[Old Price]]-tblProducts[[#This Row],[Current Price]] -> 510 | F13: 0.34 | G13: =IF(tblProducts[[#This Row],[Discount]]="","Missing",IF(tblProducts[[#This Row],[Discount]]<20%,"Low Discount",IF(tblProducts[[#This Row],[Discount]]<=40%,"Medium Discount","High Discount"))) -> Medium Discount | H13: 39 | I13: 4.7 | J13: =IF(tblProducts[[#This Row],[Rating]]="","Missing",IF(tblProducts[[#This Row],[Rating]]<3,"Poor",IF(tblProducts[[#This Row],[Rating]]<=4,"Average",IF(tblProducts[[#This Row],[Rating]]<4.5, "Unclassified","Excellent")))) -> Excellent
... A22: 3PCS Single Head Knitting Crochet Sweater Needle Set | B22: 38 | C22: 80 | D22: =IF(tblProducts[[#This Row],[Current Price]]="","Missing",IF(tblProducts[[#This Row],[Current Price]]<Price_Q1,"Low Price",IF(tblProducts[[#This Row],[Current Price]]<Price_Q3,"Medium Price","High Price"))) -> Low Price | E22: =tblProducts[[#This Row],[Old Price]]-tblProducts[[#This Row],[Current Price]] -> 42 | F22: 0.53 | G22: =IF(tblProducts[[#This Row],[Discount]]="","Missing",IF(tblProducts[[#This Row],[Discount]]<20%,"Low Discount",IF(tblProducts[[#This Row],[Discount]]<=40%,"Medium Discount","High Discount"))) -> High Discount | H22: 13 | I22: 3.3 | J22: =IF(tblProducts[[#This Row],[Rating]]="","Missing",IF(tblProducts[[#This Row],[Rating]]<3,"Poor",IF(tblProducts[[#This Row],[Rating]]<=4,"Average",IF(tblProducts[[#This Row],[Rating]]<4.5, "Unclassified","Excellent")))) -> Average
A23: 4pcs Bathroom/Kitchen Towel Rack,Roll Paper Holder,Towel Bars,Hook | B23: 1860 | C23: 3220 | D23: =IF(tblProducts[[#This Row],[Current Price]]="","Missing",IF(tblProducts[[#This Row],[Current Price]]<Price_Q1,"Low Price",IF(tblProducts[[#This Row],[Current Price]]<Price_Q3,"Medium Price","High Price"))) -> High Price | E23: =tblProducts[[#This Row],[Old Price]]-tblProducts[[#This Row],[Current Price]] -> 1360 | F23: 0.42 | G23: =IF(tblProducts[[#This Row],[Discount]]="","Missing",IF(tblProducts[[#This Row],[Discount]]<20%,"Low Discount",IF(tblProducts[[#This Row],[Discount]]<=40%,"Medium Discount","High Discount"))) -> High Discount | J23: =IF(tblProducts[[#This Row],[Rating]]="","Missing",IF(tblProducts[[#This Row],[Rating]]<3,"Poor",IF(tblProducts[[#This Row],[Rating]]<=4,"Average",IF(tblProducts[[#This Row],[Rating]]<4.5, "Unclassified","Excellent")))) -> Missing
A24: LED Romantic Spaceship Starry Sky Projector,Children's Bedroom Night Light-Blue | B24: 880 | C24: 1350 | D24: =IF(tblProducts[[#This Row],[Current Price]]="","Missing",IF(tblProducts[[#This Row],[Current Price]]<Price_Q1,"Low Price",IF(tblProducts[[#This Row],[Current Price]]<Price_Q3,"Medium Price","High Price"))) -> Medium Price | E24: =tblProducts[[#This Row],[Old Price]]-tblProducts[[#This Row],[Current Price]] -> 470 | F24: 0.35 | G24: =IF(tblProducts[[#This Row],[Discount]]="","Missing",IF(tblProducts[[#This Row],[Discount]]<20%,"Low Discount",IF(tblProducts[[#This Row],[Discount]]<=40%,"Medium Discount","High Discount"))) -> Medium Discount | H24: 6 | I24: 4 | J24: =IF(tblProducts[[#This Row],[Rating]]="","Missing",IF(tblProducts[[#This Row],[Rating]]<3,"Poor",IF(tblProducts[[#This Row],[Rating]]<=4,"Average",IF(tblProducts[[#This Row],[Rating]]<4.5, "Unclassified","Excellent")))) -> Average
A25: Foldable Overbed Table/Desk | B25: 1650 | C25: 2150 | D25: =IF(tblProducts[[#This Row],[Current Price]]="","Missing",IF(tblProducts[[#This Row],[Current Price]]<Price_Q1,"Low Price",IF(tblProducts[[#This Row],[Current Price]]<Price_Q3,"Medium Price","High Price"))) -> Medium Price | E25: =tblProducts[[#This Row],[Old Price]]-tblProducts[[#This Row],[Current Price]] -> 500 | F25: 0.23 | G25: =IF(tblProducts[[#This Row],[Discount]]="","Missing",IF(tblProducts[[#This Row],[Discount]]<20%,"Low Discount",IF(tblProducts[[#This Row],[Discount]]<=40%,"Medium Discount","High Discount"))) -> Medium Discount | H25: 14 | I25: 4.4 | J25: =IF(tblProducts[[#This Row],[Rating]]="","Missing",IF(tblProducts[[#This Row],[Rating]]<3,"Poor",IF(tblProducts[[#This Row],[Rating]]<=4,"Average",IF(tblProducts[[#This Row],[Rating]]<4.5, "Unclassified","Excellent")))) -> Unclassified
A26: LASA 3 Tier Bamboo Shoe Bench Storage Shelf | B26: 2048 | C26: 4500 | D26: =IF(tblProducts[[#This Row],[Current Price]]="","Missing",IF(tblProducts[[#This Row],[Current Price]]<Price_Q1,"Low Price",IF(tblProducts[[#This Row],[Current Price]]<Price_Q3,"Medium Price","High Price"))) -> High Price | E26: =tblProducts[[#This Row],[Old Price]]-tblProducts[[#This Row],[Current Price]] -> 2452 | F26: 0.54 | G26: =IF(tblProducts[[#This Row],[Discount]]="","Missing",IF(tblProducts[[#This Row],[Discount]]<20%,"Low Discount",IF(tblProducts[[#This Row],[Discount]]<=40%,"Medium Discount","High Discount"))) -> High Discount | H26: 7 | I26: 4.3 | J26: =IF(tblProducts[[#This Row],[Rating]]="","Missing",IF(tblProducts[[#This Row],[Rating]]<3,"Poor",IF(tblProducts[[#This Row],[Rating]]<=4,"Average",IF(tblProducts[[#This Row],[Rating]]<4.5, "Unclassified","Excellent")))) -> Unclassified
A27: Electronic Digital Display Vernier Caliper | B27: 420 | C27: 647 | D27: =IF(tblProducts[[#This Row],[Current Price]]="","Missing",IF(tblProducts[[#This Row],[Current Price]]<Price_Q1,"Low Price",IF(tblProducts[[#This Row],[Current Price]]<Price_Q3,"Medium Price","High Price"))) -> Low Price | E27: =tblProducts[[#This Row],[Old Price]]-tblProducts[[#This Row],[Current Price]] -> 227 | F27: 0.35 | G27: =IF(tblProducts[[#This Row],[Discount]]="","Missing",IF(tblProducts[[#This Row],[Discount]]<20%,"Low Discount",IF(tblProducts[[#This Row],[Discount]]<=40%,"Medium Discount","High Discount"))) -> Medium Discount | H27: 49 | I27: 4.6 | J27: =IF(tblProducts[[#This Row],[Rating]]="","Missing",IF(tblProducts[[#This Row],[Rating]]<3,"Poor",IF(tblProducts[[#This Row],[Rating]]<=4,"Average",IF(tblProducts[[#This Row],[Rating]]<4.5, "Unclassified","Excellent")))) -> Excellent
A28: Portable Wardrobe Nonwoven With 3 Hanging Rods And 6 Storage Shelves | B28: 2880 | C28: 3520 | D28: =IF(tblProducts[[#This Row],[Current Price]]="","Missing",IF(tblProducts[[#This Row],[Current Price]]<Price_Q1,"Low Price",IF(tblProducts[[#This Row],[Current Price]]<Price_Q3,"Medium Price","High Price"))) -> High Price | E28: =tblProducts[[#This Row],[Old Price]]-tblProducts[[#This Row],[Current Price]] -> 640 | F28: 0.18 | G28: =IF(tblProducts[[#This Row],[Discount]]="","Missing",IF(tblProducts[[#This Row],[Discount]]<20%,"Low Discount",IF(tblProducts[[#This Row],[Discount]]<=40%,"Medium Discount","High Discount"))) -> Low Discount | H28: 12 | I28: 3.8 | J28: =IF(tblProducts[[#This Row],[Rating]]="","Missing",IF(tblProducts[[#This Row],[Rating]]<3,"Poor",IF(tblProducts[[#This Row],[Rating]]<=4,"Average",IF(tblProducts[[#This Row],[Rating]]<4.5, "Unclassified","Excellent")))) -> Average
A29: 12 Litre Black Insulated Lunch Box | B29: 1350 | C29: 1990 | D29: =IF(tblProducts[[#This Row],[Current Price]]="","Missing",IF(tblProducts[[#This Row],[Current Price]]<Price_Q1,"Low Price",IF(tblProducts[[#This Row],[Current Price]]<Price_Q3,"Medium Price","High Price"))) -> Medium Price | E29: =tblProducts[[#This Row],[Old Price]]-tblProducts[[#This Row],[Current Price]] -> 640 | F29: 0.32 | G29: =IF(tblProducts[[#This Row],[Discount]]="","Missing",IF(tblProducts[[#This Row],[Discount]]<20%,"Low Discount",IF(tblProducts[[#This Row],[Discount]]<=40%,"Medium Discount","High Discount"))) -> Medium Discount | H29: 13 | I29: 3.8 | J29: =IF(tblProducts[[#This Row],[Rating]]="","Missing",IF(tblProducts[[#This Row],[Rating]]<3,"Poor",IF(tblProducts[[#This Row],[Rating]]<=4,"Average",IF(tblProducts[[#This Row],[Rating]]<4.5, "Unclassified","Excellent")))) -> Average
A30: 52 Pieces Cake Decorating Tool Set Gift Kit Baking Supplies | B30: 1758 | C30: 2499 | D30: =IF(tblProducts[[#This Row],[Current Price]]="","Missing",IF(tblProducts[[#This Row],[Current Price]]<Price_Q1,"Low Price",IF(tblProducts[[#This Row],[Current Price]]<Price_Q3,"Medium Price","High Price"))) -> High Price | E30: =tblProducts[[#This Row],[Old Price]]-tblProducts[[#This Row],[Current Price]] -> 741 | F30: 0.3 | G30: =IF(tblProducts[[#This Row],[Discount]]="","Missing",IF(tblProducts[[#This Row],[Discount]]<20%,"Low Discount",IF(tblProducts[[#This Row],[Discount]]<=40%,"Medium Discount","High Discount"))) -> Medium Discount | H30: 20 | I30: 4.1 | J30: =IF(tblProducts[[#This Row],[Rating]]="","Missing",IF(tblProducts[[#This Row],[Rating]]<3,"Poor",IF(tblProducts[[#This Row],[Rating]]<=4,"Average",IF(tblProducts[[#This Row],[Rating]]<4.5, "Unclassified","Excellent")))) -> Unclassified
A31: MultiFunctional Storage Rack Multi-layer Bookshelf | B31: 2200 | C31: 4080 | D31: =IF(tblProducts[[#This Row],[Current Price]]="","Missing",IF(tblProducts[[#This Row],[Current Price]]<Price_Q1,"Low Price",IF(tblProducts[[#This Row],[Current Price]]<Price_Q3,"Medium Price","High Price"))) -> High Price | E31: =tblProducts[[#This Row],[Old Price]]-tblProducts[[#This Row],[Current Price]] -> 1880 | F31: 0.46 | G31: =IF(tblProducts[[#This Row],[Discount]]="","Missing",IF(tblProducts[[#This Row],[Discount]]<20%,"Low Discount",IF(tblProducts[[#This Row],[Discount]]<=40%,"Medium Discount","High Discount"))) -> High Discount | J31: =IF(tblProducts[[#This Row],[Rating]]="","Missing",IF(tblProducts[[#This Row],[Rating]]<3,"Poor",IF(tblProducts[[#This Row],[Rating]]<=4,"Average",IF(tblProducts[[#This Row],[Rating]]<4.5, "Unclassified","Excellent")))) -> Missing
A32: Exfoliate And Exfoliate Face Towel - Black | B32: 185 | C32: 382 | D32: =IF(tblProducts[[#This Row],[Current Price]]="","Missing",IF(tblProducts[[#This Row],[Current Price]]<Price_Q1,"Low Price",IF(tblProducts[[#This Row],[Current Price]]<Price_Q3,"Medium Price","High Price"))) -> Low Price | E32: =tblProducts[[#This Row],[Old Price]]-tblProducts[[#This Row],[Current Price]] -> 197 | F32: 0.52 | G32: =IF(tblProducts[[#This Row],[Discount]]="","Missing",IF(tblProducts[[#This Row],[Discount]]<20%,"Low Discount",IF(tblProducts[[#This Row],[Discount]]<=40%,"Medium Discount","High Discount"))) -> High Discount | H32: 9 | I32: 4.3 | J32: =IF(tblProducts[[#This Row],[Rating]]="","Missing",IF(tblProducts[[#This Row],[Rating]]<3,"Poor",IF(tblProducts[[#This Row],[Rating]]<=4,"Average",IF(tblProducts[[#This Row],[Rating]]<4.5, "Unclassified","Excellent")))) -> Unclassified
A33: 12 Litre Insulated Lunch Box Grey | B33: 980 | C33: 1490 | D33: =IF(tblProducts[[#This Row],[Current Price]]="","Missing",IF(tblProducts[[#This Row],[Current Price]]<Price_Q1,"Low Price",IF(tblProducts[[#This Row],[Current Price]]<Price_Q3,"Medium Price","High Price"))) -> Medium Price | E33: =tblProducts[[#This Row],[Old Price]]-tblProducts[[#This Row],[Current Price]] -> 510 | F33: 0.34 | G33: =IF(tblProducts[[#This Row],[Discount]]="","Missing",IF(tblProducts[[#This Row],[Discount]]<20%,"Low Discount",IF(tblProducts[[#This Row],[Discount]]<=40%,"Medium Discount","High Discount"))) -> Medium Discount | H33: 12 | I33: 4.7 | J33: =IF(tblProducts[[#This Row],[Rating]]="","Missing",IF(tblProducts[[#This Row],[Rating]]<3,"Poor",IF(tblProducts[[#This Row],[Rating]]<=4,"Average",IF(tblProducts[[#This Row],[Rating]]<4.5, "Unclassified","Excellent")))) -> Excellent
A34: LED Eye Protection Desk Lamp , Study, Reading, USB Fan - Double Pen Holder | B34: 1820 | C34: 3490 | D34: =IF(tblProducts[[#This Row],[Current Price]]="","Missing",IF(tblProducts[[#This Row],[Current Price]]<Price_Q1,"Low Price",IF(tblProducts[[#This Row],[Current Price]]<Price_Q3,"Medium Price","High Price"))) -> High Price | E34: =tblProducts[[#This Row],[Old Price]]-tblProducts[[#This Row],[Current Price]] -> 1670 | F34: 0.48 | G34: =IF(tblProducts[[#This Row],[Discount]]="","Missing",IF(tblProducts[[#This Row],[Discount]]<20%,"Low Discount",IF(tblProducts[[#This Row],[Discount]]<=40%,"Medium Discount","High Discount"))) -> High Discount | H34: 9 | I34: 4.3 | J34: =IF(tblProducts[[#This Row],[Rating]]="","Missing",IF(tblProducts[[#This Row],[Rating]]<3,"Poor",IF(tblProducts[[#This Row],[Rating]]<=4,"Average",IF(tblProducts[[#This Row],[Rating]]<4.5, "Unclassified","Excellent")))) -> Unclassified
A35: 53Pcs/Set Yarn Knitting Crochet Hooks With Bag - Fortune Cat | B35: 1940 | C35: 2650 | D35: =IF(tblProducts[[#This Row],[Current Price]]="","Missing",IF(tblProducts[[#This Row],[Current Price]]<Price_Q1,"Low Price",IF(tblProducts[[#This Row],[Current Price]]<Price_Q3,"Medium Price","High Price"))) -> High Price | E35: =tblProducts[[#This Row],[Old Price]]-tblProducts[[#This Row],[Current Price]] -> 710 | F35: 0.27 | G35: =IF(tblProducts[[#This Row],[Discount]]="","Missing",IF(tblProducts[[#This Row],[Discount]]<20%,"Low Discount",IF(tblProducts[[#This Row],[Discount]]<=40%,"Medium Discount","High Discount"))) -> Medium Discount | H35: 20 | I35: 4.7 | J35: =IF(tblProducts[[#This Row],[Rating]]="","Missing",IF(tblProducts[[#This Row],[Rating]]<3,"Poor",IF(tblProducts[[#This Row],[Rating]]<=4,"Average",IF(tblProducts[[#This Row],[Rating]]<4.5, "Unclassified","Excellent")))) -> Excellent
A36: 53 Pieces/Set Yarn Knitting Crochet Hooks With Bag - Pansies | B36: 1980 | C36: 2699 | D36: =IF(tblProducts[[#This Row],[Current Price]]="","Missing",IF(tblProducts[[#This Row],[Current Price]]<Price_Q1,"Low Price",IF(tblProducts[[#This Row],[Current Price]]<Price_Q3,"Medium Price","High Price"))) -> High Price | E36: =tblProducts[[#This Row],[Old Price]]-tblProducts[[#This Row],[Current Price]] -> 719 | F36: 0.27 | G36: =IF(tblProducts[[#This Row],[Discount]]="","Missing",IF(tblProducts[[#This Row],[Discount]]<20%,"Low Discount",IF(tblProducts[[#This Row],[Discount]]<=40%,"Medium Discount","High Discount"))) -> Medium Discount | H36: 32 | I36: 4.5 | J36: =IF(tblProducts[[#This Row],[Rating]]="","Missing",IF(tblProducts[[#This Row],[Rating]]<3,"Poor",IF(tblProducts[[#This Row],[Rating]]<=4,"Average",IF(tblProducts[[#This Row],[Rating]]<4.5, "Unclassified","Excellent")))) -> Excellent
A37: DIY File Folder, Office Drawer File Holder, Pen Holder, Desktop Storage Rack | B37: 1620 | C37: 2690 | D37: =IF(tblProducts[[#This Row],[Current Price]]="","Missing",IF(tblProducts[[#This Row],[Current Price]]<Price_Q1,"Low Price",IF(tblProducts[[#This Row],[Current Price]]<Price_Q3,"Medium Price","High Price"))) -> Medium Price | E37: =tblProducts[[#This Row],[Old Price]]-tblProducts[[#This Row],[Current Price]] -> 1070 | F37: 0.4 | G37: =IF(tblProducts[[#This Row],[Discount]]="","Missing",IF(tblProducts[[#This Row],[Discount]]<20%,"Low Discount",IF(tblProducts[[#This Row],[Discount]]<=40%,"Medium Discount","High Discount"))) -> Medium Discount | H37: 1 | I37: 5 | J37: =IF(tblProducts[[#This Row],[Rating]]="","Missing",IF(tblProducts[[#This Row],[Rating]]<3,"Poor",IF(tblProducts[[#This Row],[Rating]]<=4,"Average",IF(tblProducts[[#This Row],[Rating]]<4.5, "Unclassified","Excellent")))) -> Excellent
A38: Classic Black Cat Cotton Hemp Pillow Case For Home Car | B38: 171 | C38: 360 | D38: =IF(tblProducts[[#This Row],[Current Price]]="","Missing",IF(tblProducts[[#This Row],[Current Price]]<Price_Q1,"Low Price",IF(tblProducts[[#This Row],[Current Price]]<Price_Q3,"Medium Price","High Price"))) -> Low Price | E38: =tblProducts[[#This Row],[Old Price]]-tblProducts[[#This Row],[Current Price]] -> 189 | F38: 0.53 | G38: =IF(tblProducts[[#This Row],[Discount]]="","Missing",IF(tblProducts[[#This Row],[Discount]]<20%,"Low Discount",IF(tblProducts[[#This Row],[Discount]]<=40%,"Medium Discount","High Discount"))) -> High Discount | H38: 2 | I38: 5 | J38: =IF(tblProducts[[#This Row],[Rating]]="","Missing",IF(tblProducts[[#This Row],[Rating]]<3,"Poor",IF(tblProducts[[#This Row],[Rating]]<=4,"Average",IF(tblProducts[[#This Row],[Rating]]<4.5, "Unclassified","Excellent")))) -> Excellent
A39: Punch-free Great Load Bearing Bathroom Storage Rack Wall Shelf-White | B39: 389 | C39: 656 | D39: =IF(tblProducts[[#This Row],[Current Price]]="","Missing",IF(tblProducts[[#This Row],[Current Price]]<Price_Q1,"Low Price",IF(tblProducts[[#This Row],[Current Price]]<Price_Q3,"Medium Price","High Price"))) -> Low Price | E39: =tblProducts[[#This Row],[Old Price]]-tblProducts[[#This Row],[Current Price]] -> 267 | F39: 0.41 | G39: =IF(tblProducts[[#This Row],[Discount]]="","Missing",IF(tblProducts[[#This Row],[Discount]]<20%,"Low Discount",IF(tblProducts[[#This Row],[Discount]]<=40%,"Medium Discount","High Discount"))) -> High Discount | H39: 36 | I39: 4.3 | J39: =IF(tblProducts[[#This Row],[Rating]]="","Missing",IF(tblProducts[[#This Row],[Rating]]<3,"Poor",IF(tblProducts[[#This Row],[Rating]]<=4,"Average",IF(tblProducts[[#This Row],[Rating]]<4.5, "Unclassified","Excellent")))) -> Unclassified
A40: 1/2/3 Seater Elastic Sofa Cover,Living Room/Home Decor Chair Cover-Grey | B40: 1800 | C40: 2700 | D40: =IF(tblProducts[[#This Row],[Current Price]]="","Missing",IF(tblProducts[[#This Row],[Current Price]]<Price_Q1,"Low Price",IF(tblProducts[[#This Row],[Current Price]]<Price_Q3,"Medium Price","High Price"))) -> High Price | E40: =tblProducts[[#This Row],[Old Price]]-tblProducts[[#This Row],[Current Price]] -> 900 | F40: 0.38 | G40: =IF(tblProducts[[#This Row],[Discount]]="","Missing",IF(tblProducts[[#This Row],[Discount]]<20%,"Low Discount",IF(tblProducts[[#This Row],[Discount]]<=40%,"Medium Discount","High Discount"))) -> Medium Discount | H40: 2 | I40: 4.5 | J40: =IF(tblProducts[[#This Row],[Rating]]="","Missing",IF(tblProducts[[#This Row],[Rating]]<3,"Poor",IF(tblProducts[[#This Row],[Rating]]<=4,"Average",IF(tblProducts[[#This Row],[Rating]]<4.5, "Unclassified","Excellent")))) -> Excellent
A41: LASA Stainless Steel Double Wall Mount Soap Dispenser - 500ml | B41: 2750 | C41: 4471 | D41: =IF(tblProducts[[#This Row],[Current Price]]="","Missing",IF(tblProducts[[#This Row],[Current Price]]<Price_Q1,"Low Price",IF(tblProducts[[#This Row],[Current Price]]<Price_Q3,"Medium Price","High Price"))) -> High Price | E41: =tblProducts[[#This Row],[Old Price]]-tblProducts[[#This Row],[Current Price]] -> 1721 | F41: 0.38 | G41: =IF(tblProducts[[#This Row],[Discount]]="","Missing",IF(tblProducts[[#This Row],[Discount]]<20%,"Low Discount",IF(tblProducts[[#This Row],[Discount]]<=40%,"Medium Discount","High Discount"))) -> Medium Discount | J41: =IF(tblProducts[[#This Row],[Rating]]="","Missing",IF(tblProducts[[#This Row],[Rating]]<3,"Poor",IF(tblProducts[[#This Row],[Rating]]<=4,"Average",IF(tblProducts[[#This Row],[Rating]]<4.5, "Unclassified","Excellent")))) -> Missing
A42: 4M Float Switch Water Level Controller -Water Tank | B42: 475 | C42: 931 | D42: =IF(tblProducts[[#This Row],[Current Price]]="","Missing",IF(tblProducts[[#This Row],[Current Price]]<Price_Q1,"Low Price",IF(tblProducts[[#This Row],[Current Price]]<Price_Q3,"Medium Price","High Price"))) -> Low Price | E42: =tblProducts[[#This Row],[Old Price]]-tblProducts[[#This Row],[Current Price]] -> 456 | F42: 0.49 | G42: =IF(tblProducts[[#This Row],[Discount]]="","Missing",IF(tblProducts[[#This Row],[Discount]]<20%,"Low Discount",IF(tblProducts[[#This Row],[Discount]]<=40%,"Medium Discount","High Discount"))) -> High Discount | J42: =IF(tblProducts[[#This Row],[Rating]]="","Missing",IF(tblProducts[[#This Row],[Rating]]<3,"Poor",IF(tblProducts[[#This Row],[Rating]]<=4,"Average",IF(tblProducts[[#This Row],[Rating]]<4.5, "Unclassified","Excellent")))) -> Missing
A43: Modern Sofa Throw Pillow Cover-45x45cm-Blue&Red | B43: 238 | C43: 476 | D43: =IF(tblProducts[[#This Row],[Current Price]]="","Missing",IF(tblProducts[[#This Row],[Current Price]]<Price_Q1,"Low Price",IF(tblProducts[[#This Row],[Current Price]]<Price_Q3,"Medium Price","High Price"))) -> Low Price | E43: =tblProducts[[#This Row],[Old Price]]-tblProducts[[#This Row],[Current Price]] -> 238 | F43: 0.5 | G43: =IF(tblProducts[[#This Row],[Discount]]="","Missing",IF(tblProducts[[#This Row],[Discount]]<20%,"Low Discount",IF(tblProducts[[#This Row],[Discount]]<=40%,"Medium Discount","High Discount"))) -> High Discount | J43: =IF(tblProducts[[#This Row],[Rating]]="","Missing",IF(tblProducts[[#This Row],[Rating]]<3,"Poor",IF(tblProducts[[#This Row],[Rating]]<=4,"Average",IF(tblProducts[[#This Row],[Rating]]<4.5, "Unclassified","Excellent")))) -> Missing
A44: Balloon Insert, Birthday Party Balloon Set, PU Leather | B44: 610 | C44: 1060 | D44: =IF(tblProducts[[#This Row],[Current Price]]="","Missing",IF(tblProducts[[#This Row],[Current Price]]<Price_Q1,"Low Price",IF(tblProducts[[#This Row],[Current Price]]<Price_Q3,"Medium Price","High Price"))) -> Medium Price | E44: =tblProducts[[#This Row],[Old Price]]-tblProducts[[#This Row],[Current Price]] -> 450 | F44: 0.42 | G44: =IF(tblProducts[[#This Row],[Discount]]="","Missing",IF(tblProducts[[#This Row],[Discount]]<20%,"Low Discount",IF(tblProducts[[#This Row],[Discount]]<=40%,"Medium Discount","High Discount"))) -> High Discount | J44: =IF(tblProducts[[#This Row],[Rating]]="","Missing",IF(tblProducts[[#This Row],[Rating]]<3,"Poor",IF(tblProducts[[#This Row],[Rating]]<=4,"Average",IF(tblProducts[[#This Row],[Rating]]<4.5, "Unclassified","Excellent")))) -> Missing
A45: Shower Cap Wide Elastic Band Cover Reusable Bashroom Cap | B45: 2132 | C45: 2169 | D45: =IF(tblProducts[[#This Row],[Current Price]]="","Missing",IF(tblProducts[[#This Row],[Current Price]]<Price_Q1,"Low Price",IF(tblProducts[[#This Row],[Current Price]]<Price_Q3,"Medium Price","High Price"))) -> High Price | E45: =tblProducts[[#This Row],[Old Price]]-tblProducts[[#This Row],[Current Price]] -> 37 | F45: 0.02 | G45: =IF(tblProducts[[#This Row],[Discount]]="","Missing",IF(tblProducts[[#This Row],[Discount]]<20%,"Low Discount",IF(tblProducts[[#This Row],[Discount]]<=40%,"Medium Discount","High Discount"))) -> Low Discount | J45: =IF(tblProducts[[#This Row],[Rating]]="","Missing",IF(tblProducts[[#This Row],[Rating]]<3,"Poor",IF(tblProducts[[#This Row],[Rating]]<=4,"Average",IF(tblProducts[[#This Row],[Rating]]<4.5, "Unclassified","Excellent")))) -> Missing
A46: Christmas Elk Fence Yard Lawn Decorations Cute For Holidays | B46: 999 | C46: 2000 | D46: =IF(tblProducts[[#This Row],[Current Price]]="","Missing",IF(tblProducts[[#This Row],[Current Price]]<Price_Q1,"Low Price",IF(tblProducts[[#This Row],[Current Price]]<Price_Q3,"Medium Price","High Price"))) -> Medium Price | E46: =tblProducts[[#This Row],[Old Price]]-tblProducts[[#This Row],[Current Price]] -> 1001 | F46: 0.5 | G46: =IF(tblProducts[[#This Row],[Discount]]="","Missing",IF(tblProducts[[#This Row],[Discount]]<20%,"Low Discount",IF(tblProducts[[#This Row],[Discount]]<=40%,"Medium Discount","High Discount"))) -> High Discount | J46: =IF(tblProducts[[#This Row],[Rating]]="","Missing",IF(tblProducts[[#This Row],[Rating]]<3,"Poor",IF(tblProducts[[#This Row],[Rating]]<=4,"Average",IF(tblProducts[[#This Row],[Rating]]<4.5, "Unclassified","Excellent")))) -> Missing
A47: 60W Hot Melt Glue Sprayer - Efficient And Stable Glue Dispensing | B47: 1190 | C47: 1785 | D47: =IF(tblProducts[[#This Row],[Current Price]]="","Missing",IF(tblProducts[[#This Row],[Current Price]]<Price_Q1,"Low Price",IF(tblProducts[[#This Row],[Current Price]]<Price_Q3,"Medium Price","High Price"))) -> Medium Price | E47: =tblProducts[[#This Row],[Old Price]]-tblProducts[[#This Row],[Current Price]] -> 595 | F47: 0.33 | G47: =IF(tblProducts[[#This Row],[Discount]]="","Missing",IF(tblProducts[[#This Row],[Discount]]<20%,"Low Discount",IF(tblProducts[[#This Row],[Discount]]<=40%,"Medium Discount","High Discount"))) -> Medium Discount | J47: =IF(tblProducts[[#This Row],[Rating]]="","Missing",IF(tblProducts[[#This Row],[Rating]]<3,"Poor",IF(tblProducts[[#This Row],[Rating]]<=4,"Average",IF(tblProducts[[#This Row],[Rating]]<4.5, "Unclassified","Excellent")))) -> Missing
A48: Car Phone Charging Stand | B48: 671 | C48: 1316 | D48: =IF(tblProducts[[#This Row],[Current Price]]="","Missing",IF(tblProducts[[#This Row],[Current Price]]<Price_Q1,"Low Price",IF(tblProducts[[#This Row],[Current Price]]<Price_Q3,"Medium Price","High Price"))) -> Medium Price | E48: =tblProducts[[#This Row],[Old Price]]-tblProducts[[#This Row],[Current Price]] -> 645 | F48: 0.49 | G48: =IF(tblProducts[[#This Row],[Discount]]="","Missing",IF(tblProducts[[#This Row],[Discount]]<20%,"Low Discount",IF(tblProducts[[#This Row],[Discount]]<=40%,"Medium Discount","High Discount"))) -> High Discount | J48: =IF(tblProducts[[#This Row],[Rating]]="","Missing",IF(tblProducts[[#This Row],[Rating]]<3,"Poor",IF(tblProducts[[#This Row],[Rating]]<=4,"Average",IF(tblProducts[[#This Row],[Rating]]<4.5, "Unclassified","Excellent")))) -> Missing
...

Sheet Analysis
A1: Price Category
A2: Price_Q1 | B2: =_xlfn.QUARTILE.INC(tblProducts[Current Price],1) -> 493 | D2: Item | E2: Coefficient
A3: Price_Q3 | B3: =_xlfn.QUARTILE.INC(tblProducts[Current Price],3) -> 1669.5 | D3: Discount vs Review | E3: =CORREL(tblProducts[Discount],tblProducts[Review]) -> -0.13682272
D4: Rating vs Review | E4: =CORREL(tblProducts[Rating],tblProducts[Review]) -> 0.057209035
D5: Current Price vs Rating | E5: =CORREL(tblProducts[Current Price],tblProducts[Rating]) -> 0.11009021
A7: Item | B7: Value
A8: Total Products | B8: =ROWS(tblProducts[Product]) -> 112
A9: Avearage Current Price | B9: =AVERAGE(tblProducts[Current Price]) -> 1186.8929
A10: Average Old Price | B10: =AVERAGE(tblProducts[Old Price]) -> 1811.1071
A11: Average Discount | B11: =AVERAGE(tblProducts[Discount]) -> 0.36776786
A12: Average Rating | B12: =AVERAGE(tblProducts[Rating]) -> 3.8894737
A13: Total Reviews | B13: =SUM(tblProducts[Review]) -> 723
A14: Most Expensive Price | B14: =MAX(tblProducts[Current Price]) -> 3750
A15: Least Expensive Price | B15: =MIN(tblProducts[Current Price]) -> 38
A18: Products Associated with Extremes.
A19: Max Current Price | B19: =_xlfn.XLOOKUP($B$14,tblProducts[Current Price],tblProducts[Product]) -> 32PCS Portable Cordless Drill Set With Cyclic Battery Drive -26 Variable Speed
A20: Minimum Current Price | B20: =_xlfn.XLOOKUP($B$15,tblProducts[Current Price],tblProducts[Product]) -> 3PCS Single Head Knitting Crochet Sweater Needle Set

Sheet Pivot Tables
U3: Row Labels | V3: Count of Product
B4: Row Labels | C4: Count of Product | E4: Row Labels | F4: Average of Rating | U4: Average | V4: 13
B5: High Discount | C5: 62 | E5: Low Price | F5: 3.6357143 | U5: Excellent | V5: 23
B6: Medium Discount | C6: 32 | E6: Medium Price | F6: 3.8833333 | U6: Missing | V6: 55
B7: Low Discount | C7: 18 | E7: High Price | F7: 4.0842105 | U7: Poor | V7: 12
B8: Grand Total | C8: 112 | E8: Grand Total | F8: 3.8894737 | U8: Unclassified | V8: 9
U9: Grand Total | V9: 112
B14: Row Labels | C14: Average of Rating | E14: Row Labels | F14: Sum of Review
B15: Classic Black Cat Cotton Hemp Pillow Case For Home Car | C15: 5 | E15: 120W Cordless Vacuum Cleaners Handheld Electric Vacuum Cleaner | F15: 69
B16: LASA Aluminum Folding Truck Hand Cart - 68kg Max | C16: 5 | E16: 137 Pieces Cake Decorating Tool Set Baking Supplies | F16: 55
B17: Konka Healty Electric Kettle, 24-hour Heat Preservation,1.5L,800W, White | C17: 5 | E17: Electronic Digital Display Vernier Caliper | F17: 49
B18: Anti-Skid Absorbent Insulation Coaster For Home Office | C18: 5 | E18: 3D Waterproof EVA Plastic Shower Curtain 1.8*2Mtrs | F18: 44
B19: Peacock Throw Pillow Cushion Case For Home Car | C19: 5 | E19: 100 Pcs Crochet Hook Tool Set Knitting Hook Set With Box | F19: 39
B20: Bedroom Simple Floor Hanging Clothes Rack Single Pole Hat Rack - White | C20: 5 | E20: Punch-free Great Load Bearing Bathroom Storage Rack Wall Shelf-White | F20: 36
B21: DIY File Folder, Office Drawer File Holder, Pen Holder, Desktop Storage Rack | C21: 5 | E21: 53 Pieces/Set Yarn Knitting Crochet Hooks With Bag - Pansies | F21: 32
B22: LASA FOLDING TABLE SERVING STAND | C22: 4.8 | E22: Portable Mini Cordless Car Vacuum Cleaner - Blue | F22: 24
B23: Portable Home Small Air Humidifier 3-Speed Fan - Green | C23: 4.8 | E23: 52 Pieces Cake Decorating Tool Set Gift Kit Baking Supplies | F23: 20
B24: 40cm Gold DIY Acrylic Wall Sticker Clock | C24: 4.8 | E24: 53Pcs/Set Yarn Knitting Crochet Hooks With Bag - Fortune Cat | F24: 20
B25: Grand Total | C25: 4.94 | E25: Grand Total | F25: 388
E31: Row Labels | F31: Average of Discount
B32: Row Labels | C32: Sum of Review | E32: 6 In 1 Bottle Can Opener Multifunctional Easy Opener | F32: 0.64
B33: Medium Discount | C33: 351 | E33: LASA FOLDING TABLE SERVING STAND | F33: 0.55
B34: High Discount | C34: 334 | E34: 5-PCS Stainless Steel Cooking Pot Set With Steamed Slices | F34: 0.55
B35: Low Discount | C35: 38 | E35: Creative Owl Shape Keychain Black | F35: 0.55
B36: Grand Total | C36: 723 | E36: LASA 3 Tier Bamboo Shoe Bench Storage Shelf | F36: 0.54
E37: Mythco 120COB Solar Wall Ligt With Motion Sensor And Remote Control 3 Modes | F37: 0.54
E38: Classic Black Cat Cotton Hemp Pillow Case For Home Car | F38: 0.53
E39: 3PCS Single Head Knitting Crochet Sweater Needle Set | F39: 0.53
E40: Exfoliate And Exfoliate Face Towel - Black | F40: 0.52
E41: Intelligent LED Body Sensor Wireless Lighting Night Light USB | F41: 0.52
E42: Grand Total | F42: 0.54727273
F59: Review | G59: (Multiple Items)
B60: Rating | C60: (Multiple Items) | F60: Rating | G60: (Multiple Items)
B62: Row Labels | C62: Average of Rating | D62: Sum of Discount | F62: Row Labels | G62: Average of Review | H62: Average of Rating
B63: 5-PCS Stainless Steel Cooking Pot Set With Steamed Slices | C63: 2.1 | D63: 0.55 | F63: 5-PCS Stainless Steel Cooking Pot Set With Steamed Slices | G63: 13 | H63: 2.1
B64: 380ML USB Rechargeable Portable Small Blenders And Juicers | C64: 2.3 | D64: 0.5 | F64: 380ML USB Rechargeable Portable Small Blenders And Juicers | G64: 7 | H64: 2.3
B65: Wall-mounted Sticker Punch-free Plug Fixer | C65: 2 | D65: 0.5 | F65: Electric LED UV Mosquito Killer Lamp, Outdoor/Indoor Fly Killer Trap Light -USB | G65: 7 | H65: 2.1
B66: Electric LED UV Mosquito Killer Lamp, Outdoor/Indoor Fly Killer Trap Light -USB | C66: 2.1 | D66: 0.47 | F66: 7-piece Set Of Storage Bags, Travel Storage Bags, Shoe Bags | G66: 6 | H66: 2.2
B67: 7-piece Set Of Storage Bags, Travel Storage Bags, Shoe Bags | C67: 2.2 | D67: 0.47 | F67: Watercolour Gold Foil Textured Print Pillow Cover | G67: 6 | H67: 2.3
B68: Artificial Potted Flowers Room Decorative Flowers (2 Pieces) | C68: 2.2 | D68: 0.45 | F68: Artificial Potted Flowers Room Decorative Flowers (2 Pieces) | G68: 6 | H68: 2.2
...

Sheet Charts

Sheet Dashboard

Sheet Data Dictionary
A1: Data Quality Audit
A2: Number of Rows | B2: 116
A3: Number of Columns | B3: 6
A5: Issue | B5: Rows Affected | C5: Decision | D5: Reason
A6: Non-numeric Prices both Current and Old Prices | B6: {=SUMPRODUCT(--ISTEXT('Raw Data'!$B$2:$C$116))} -> 230 | C6: Convert to Number/Currency | D6: Prices are always formatted to currency, the reason might be mis-interpretation of the data format during scrapping.
A7: Discounts | B7: {=SUMPRODUCT(--ISTEXT('Raw Data'!$D$2:$D$116))} -> 0 | C7: Convert to percentages
A8: Negative Review Values | B8: =COUNTIF('Raw Data'!$E$1:$E$116, "<0") -> 57 | C8: Convert itno absolute values | D8: Convert to absolute whole numbers. Review counts can not be negative. The negative sigh is considered as a scrapping artifact.
A9: Text Type Ratings | B9: {=SUMPRODUCT(--ISTEXT('Raw Data'!$F$2:$F$116))} -> 57 | C9: Convert to Number with 1 decimal place | D9: Reviews are continous measures. The error might result from web scrapping anomalies. Replaced the out of 5 with blank, then converted to Number type.
A10: Ratings outside 0 - 5 | B10: =COUNTIF('Cleaned Data'!$I$2:$I$113,">5") + COUNTIF('Cleaned Data'!$F$2:$F$113,"<0") -> 0 | C10: All ratings are between 0 and 5
A11: Discounts ouside 0-100% | B11: =COUNTIF('Cleaned Data'!$F$2:$F$113, ">100") + COUNTIF('Cleaned Data'!$F$2:$F$113,"<0") -> 0 | C11: All discounts are between 0 - 100%
A12: Price Ranges | B12: =COUNTIF('Cleaned Data'!$B$2:$C$113,"*") -> 0 | C12: Converted them to currency | D12: Prices are always formatted to currency, the reason might be mis-interpretation of the data format during scrapping. Calculated the midpoint price and used it instead. That is price =( Lower Price + Higher)/2
A13: Duplicates and Field used to identify duplicates. | B13: 3 | C13: Removed them, Used all fields | D13: Duplicates can result from errors while scrapping and wrangling data. Since we will be dealing with each product there is no need to have duplicates. They will increase redundancy leading to inaccuracy.
A14: Current Prices greater than old prices | B14: {=SUMPRODUCT(--(tblProducts[Current Price]>tblProducts[Old Price]))} -> 0 | C14: All current prices are less than old prices.
A15: Mispelt Titles | B15: 1 | C15: Corrected the spelling of the title from Ratingd to Rating | D15: Corrected the spelling of the word by selecting the cell and typing in the new word with the correct spelling.
A16: Trailing White Spaces and extra spaces | B16: All Rows in column 1 | C16: Remove the trailling and expra spaces | D16: Used the TRIM() function to clean and remove extra and whiter spaces before and after text in all columns and rows for consistency and easy loading of data.
A17: Price_Q1 | B17: 493 | C17: 1st Quartile for current prices | D17: Used to show to customers products that have are from the low price category.
A18: Price_Q3 | B18: 1669.5 | C18: 3rd Quartile for current prices. | D18: Used to show to customers products that have are from the high price category.
A19: Mismatching header cases | B19: 2 | C19: Formatted the header to proper case | D19: For consistency avoid errors changed the "old price" and "Current price" to proper case.
